Workbook
Name age_start: '3_Parameters'!$B$11
Name Az_11: '4_Transitions'!$B$4
Name Az_12: '4_Transitions'!$C$4
Name Az_13: '4_Transitions'!$D$4
Name Az_14: '4_Transitions'!$E$4
Name Az_21: '4_Transitions'!$B$5
Name Az_22: '4_Transitions'!$C$5
Name Az_23: '4_Transitions'!$D$5
Name Az_24: '4_Transitions'!$E$5
Name Az_31: '4_Transitions'!$B$6
Name Az_32: '4_Transitions'!$C$6
Name Az_33: '4_Transitions'!$D$6
Name Az_34: '4_Transitions'!$E$6
Name Az_41: '4_Transitions'!$B$7
Name Az_42: '4_Transitions'!$C$7
Name Az_43: '4_Transitions'!$D$7
Name Az_44: '4_Transitions'!$E$7
Name C_1: '3_Parameters'!$C$46
Name C_2: '3_Parameters'!$D$46
Name C_3: '3_Parameters'!$E$46
Name C_4: '3_Parameters'!$E$47
Name c_aza: '3_Parameters'!$D$27
Name c_eve: '3_Parameters'!$D$26
Name dec_2: '3_Parameters'!$B$37
Name dec_3: '3_Parameters'!$B$38
Name disc: '3_Parameters'!$B$7
Name ev_11: '4_Transitions'!$B$13
Name ev_12: '4_Transitions'!$C$13
Name ev_13: '4_Transitions'!$D$13
Name ev_14: '4_Transitions'!$E$13
Name ev_21: '4_Transitions'!$B$14
Name ev_22: '4_Transitions'!$C$14
Name ev_23: '4_Transitions'!$D$14
Name ev_24: '4_Transitions'!$E$14
Name ev_31: '4_Transitions'!$B$15
Name ev_32: '4_Transitions'!$C$15
Name ev_33: '4_Transitions'!$D$15
Name ev_34: '4_Transitions'!$E$15
Name ev_41: '4_Transitions'!$B$16
Name ev_42: '4_Transitions'!$C$16
Name ev_43: '4_Transitions'!$D$16
Name ev_44: '4_Transitions'!$E$16
Name horizon: '3_Parameters'!$B$5
Name ICER: '7_Results'!$G$7
Name LY_aza: '5_Markov_SC'!$J$38
Name LY_eve: '6_Markov_EVE'!$J$38
Name mean_gap: '3_Parameters'!$B$13
Name n_cohort: '3_Parameters'!$B$4
Name RR: '3_Parameters'!$B$20
Name share_male: '3_Parameters'!$B$12
Name TC_disc_ev: '6_Markov_EVE'!$R$38
Name TC_disc_sc: '5_Markov_SC'!$R$38
Name Thre_HIGH: '3_Parameters'!$B$10
Name Thre_LOW: '3_Parameters'!$B$8
Name Thre_MID: '3_Parameters'!$B$9
Name TQ_disc_ev: '6_Markov_EVE'!$X$38
Name TQ_disc_sc: '5_Markov_SC'!$X$38
Name u_1: '3_Parameters'!$B$33
Name u_2: '3_Parameters'!$B$34
Name u_3: '3_Parameters'!$B$35

Sheet 1_plan
A1: Everolimus vs azathioprine after heart transplant: Markov cohort model
A3: 1. Decision problem
A4: Question | B4: Is everolimus cost-effective compared with azathioprine for preventing cardiac allograft vasculopathy (CAV) in adult heart transplant recipients in the UK?
A5: Population | B5: Adult heart transplant recipients with no CAV at their first angiogram. Starting age and share of men come from the cav cohort (see 3_Parameters).
A6: Intervention | B6: Everolimus
A7: Comparator | B7: Azathioprine (standard care). The cav cohort represents standard care.
A8: Perspective | B8: NHS and Personal Social Services
A9: Time horizon | B9: 30 years, annual cycles
A10: Discounting | B10: 3.5% a year for costs and QALYs (NICE)
A11: Outcomes | B11: Costs, life years, QALYs, ICER, and net monetary benefit (NMB)
A12: Threshold | B12: £25,000 to £35,000 per QALY (NICE)
A14: 2. Health states
A15: State 1 | B15: No CAV (0% stenosis)
A16: State 2 | B16: Mild or moderate CAV (stenosis up to 70%)
A17: State 3 | B17: Severe CAV (stenosis over 70%)
A18: State 4 | B18: Death (absorbing)
A19: Allowed moves | B19: 1 → 1, 2, 3, 4 | 2 → 2, 3, 4 | 3 → 3, 4 | 4 → 4. No backward moves.
A20: Diagram | B20: State 1 → State 2 → State 3, and every alive state → Death
A22: 3. Data sources
A23: Transitions | B23: cav dataset from the R package msm (Papworth Hospital; Sharples et al. 2003, Transplantation 76(4):679-682). 622 patients, 2,846 angiograms. Exported with scripts/01_get_data.R, counted with scripts/02_transitions.sql, stored in 2_Data.
A24: Treatment effect | B24: Relative risk of CAV for everolimus 1.5 mg vs azathioprine, calculated from the 12-month incidence of vasculopathy in Eisen et al. 2003, NEJM 349(9):847-858 (35.7% vs 52.8%). See 3_Parameters.
A25: Utilities and costs | B25: Published UK sources or labelled assumptions (see 3_Parameters)
A26: Background mortality | B26: ONS National Life Tables, UK, 2022 to 2024
A28: 4. Model structure
A29: Model type | B29: Markov cohort model in Excel. 1,000 people start in state 1.
A30: Standard care | B30: Transition probabilities = transition counts in each row ÷ row total (4_Transitions)
A31: Everolimus | B31: Standard-care probabilities of moving 1 → 2 and 1 → 3 are multiplied by the relative risk. Death from state 1 is unchanged. Staying in state 1 takes the remainder.
A32: Background mortality | B32: Each cycle, death probability = the larger of the model's death probability and the ONS qx at the cohort's current age
A33: Half-cycle correction | B33: Applied to costs, life years and QALYs
A34: Results | B34: ICER, NMB, threshold price for everolimus (Goal Seek), state occupancy chart
A35: Sensitivity analysis | B35: Deterministic: one-way analysis with a tornado diagram. Probabilistic: 1,000 iterations, cost-effectiveness plane and acceptability curve.
A37: 5. Assumptions
A38: A1 | B38: Transitions use statemax (the worst state reached so far). CAV cannot improve. Apparent improvements are treated as angiogram misclassification.
A39: A2 | B39: The time between angiograms is treated as one cycle (one year). The mean gap is shown in 2_Data.
A40: A3 | B40: Transition probabilities do not change with time since transplant.
A41: A4 | B41: Everolimus lowers progression out of state 1 only. It has no effect once CAV is present and no direct effect on death.
A42: A5 | B42: The treatment effect lasts for the whole time horizon.
A43: A6 | B43: Costs and utilities depend only on the health state. Everolimus is taken while alive.
A44: A7 | B44: Adverse events and treatment switching are not modelled.
A45: A8 | B45: The 1.5 mg dose is used because it is the usual dose. The 12-month relative risk from the trial is applied in every annual cycle.
...

Sheet 2_Data
A1: cohort_characteristics | F1: (01_SQL.sql results)
A3: patients | B3: mean_age_at_transplant | C3: min_age | D3: max_age | E3: share_male
A4: 622 | B4: 47.1 | C4: 6.3041096 | D4: 64.260274 | E4: 0.86
A6: mean_gap_years | B6: min_gap | C6: max_gap | D6: gaps_over_1_5_years | E6: all_gaps
A7: 1.65 | B7: 0 | C7: 16.48 | D7: 1093 | E7: 2224
A10: Transition_Matrix | D10: Azathioprine (standard care) | F10: (01_SQL.sql results)
A13: from_state | B13: to_1 | C13: to_2 | D13: to_3 | E13: to_4 | F13: total
A14: from_1 | B14: 1336 | C14: 185 | D14: 40 | E14: 139 | F14: =SUM(B14:E14) -> 1700
A15: from_2 | B15: 0 | C15: 220 | D15: 52 | E15: 49 | F15: =SUM(B15:E15) -> 321
A16: from_3 | B16: 0 | C16: 0 | D16: 140 | E16: 63 | F16: =SUM(B16:E16) -> 203
A18: 1 = no CAV; 2 = mild/moderate CAV; 3 = severe CAV; 4 = death
A21: National Life Tables, United Kingdom, period expectation of life, based on data for the years 2022-2024
A24: age | B24: qx (Males) | C24: qx (Females)
A25: 0 | B25: 0.004602 | C25: 0.003631
A26: 1 | B26: 0.000247 | C26: 0.000206
A27: 2 | B27: 0.000177 | C27: 0.000137
A28: 3 | B28: 0.000115 | C28: 9.9e-05
A29: 4 | B29: 0.0001 | C29: 8.1e-05
A30: 5 | B30: 9.7e-05 | C30: 7e-05
A31: 6 | B31: 8e-05 | C31: 7.5e-05
A32: 7 | B32: 8e-05 | C32: 6.2e-05
A33: 8 | B33: 7.9e-05 | C33: 6.1e-05
A34: 9 | B34: 9.1e-05 | C34: 6e-05
A35: 10 | B35: 7e-05 | C35: 7.6e-05
A36: 11 | B36: 9.5e-05 | C36: 6.2e-05
... A125: 100 | B125: 0.402489 | C125: 0.349105

Sheet 3_Parameters
A1: 1. General settings
A3: Parameter | B3: Value | C3: Source
A4: Cohort size | B4: 1000 | C4: Choice
A5: Time horizon (years) | B5: 30 | C5: Choice
A6: Cycle length | B6: 1 year | C6: Choice
A7: Discount rate, costs and QALYs | B7: 0.035 | C7: NICE
A8: Threshold:low | B8: 25000 | C8: NICE
A9: Threshold | B9: 30000 | C9: NICE
A10: Threshold:high | B10: 35000 | C10: NICE
A11: Starting age | B11: ='2_Data'!B4 -> 47.1 | C11: cav data, SQL
A12: Share of men | B12: ='2_Data'!E4 -> 0.86 | C12: cav data, SQL
A13: Mean time between angiograms | B13: ='2_Data'!A$7 -> 1.65 | C13: cav data, SQL
A15: 2. Treatment effect: everolimus vs azathioprine (Eisen et al. 2003)
A17: Description | B17: Value | C17: Source
A18: CAV risk, everolimus 1.5 mg | B18: 0.357 | C18: Eisen 2003, abstract
A19: CAV risk, azathioprine | B19: 0.528 | C19: Eisen 2003, abstract
A20: Relative risk (RR) (for CAV risk) | B20: =B18/B19 -> 0.67613636 | C20: Calculated
A23: 3. Drug costs
A25: Drug | B25: Pack price | C25: Dose (assumption) | D25: Annual cost | E25: source
A26: Everolimus (Certican 0.75 mg, 60 tablets) | B26: 445.5 | C26: 0.75 mg twice a day = 2 tablets | D26: =B26/60*2*365 -> 5420.25 | E26: https://bnf.nice.org.uk/drugs/everolimus/medicinal-forms/
A27: Azathioprine 50 mg, 56 tablets | B27: 1.4 | C27: ~2 mg/kg for a 70 kg adult = 3 tablets | D27: =(365/(56/3)* B27) -> 27.375 | E27: https://bnf.nice.org.uk/drugs/azathioprine/medicinal-forms/
A30: 4. Utilities
A32: State | B32: Value | C32: Source
A33: 1, no CAV | B33: 0.76 | C33: https://doi.org/10.3310/hta10480
A34: 2, mild/moderate CAV | B34: =u_1-dec_2 -> 0.71 | C34: calculated
A35: 3, severe CAV | B35: =u_1-dec_3 -> 0.61 | C35: calculated
A36: 4, death | B36: 0 | C36: –
A37: Decrements of mild/moderate CAV | B37: 0.05 | C37: Assumption
A38: Decrements of severe CAV | B38: 0.15 | C38: Assumption
A40: 5. State costs (annual, excluding the study drugs)
A42: Item | B42: Unit cost (£) | C42: State 1: no CAV | D42: State 2: mild/moderate | E42: State 3: severe | F42: Source
A43: Clinic follow-up visit (consultant-led outpatient) | B43: 203 | C43: 4 | D43: 6 | E43: 8 | F43: Cost: Jones et al., Unit Costs of Health and Social Care 2025, Table 6.1.1 (NCC 2024/25), https://kar.kent.ac.uk/115569/. Visits per year: assumption
A44: Coronary angiogram (HRG EY43, standard cardiac catheterisation) | B44: 1685 | C44: 1 | D44: 1 | E44: 1 | F44: Cost: NICE MTG32, section 5.13, https://www.nice.org.uk/guidance/mtg32/chapter/5-Cost-considerations. Once a year: ISHLT 2023 guideline (annual or biannual angiography)
A45: PCI with stent (HRG EY41, standard PTCA) | B45: 2725 | C45: 0 | D45: 0 | E45: 0.1 | F45: Cost: ORBITA economic evaluation (NHS Reference Costs 2017/18), https://pmc.ncbi.nlm.nih.gov/articles/PMC7875263. Share: Prada-Delgado et al. 2012, Transplant Proc 44(9):2657-9 (27.9% revascularised over ~3 years ≈ 10% a year)
A46: Annual state cost (c_1, c_2, c_3) | C46: =($B$43*C43)+($B$44*C44)+($B$45*C45) -> 2497 | D46: =($B$43*D43)+($B$44*D44)+($B$45*D45) -> 2903 | E46: =($B$43*E43)+($B$44*E44)+($B$45*E45) -> 3581.5 | F46: Calculated: visits × 203 + angiograms × 1,685 + PCI share × 2,725
A47: Death (c_4) | E47: 0 | F47: No costs after death
A50: 6. Background mortality: probability of death by age | E50: qx weighted by the share of men in the cohort. Used as the minimum death probability in each cycle
A52: Cycle | B52: Age | C52: qx male | D52: qx female | E52: qx weighted
A53: 1 | B53: =ROUND('2_Data'!$B$4,0) -> 47 | C53: =_xlfn.XLOOKUP('3_Parameters'!$B53,'2_Data'!$A$25:$A$125,'2_Data'!$B$25:$B$125) -> 0.002839 | D53: =_xlfn.XLOOKUP('3_Parameters'!$B53,'2_Data'!$A$25:$A$125,'2_Data'!$C$25:$C$125) -> 0.001777 | E53: =(C53*share_male)+(D53*(1-share_male)) -> 0.00269032
A54: 2 | B54: =ROUND(B53,0)+1 -> 48 | C54: =_xlfn.XLOOKUP('3_Parameters'!$B54,'2_Data'!$A$25:$A$125,'2_Data'!$B$25:$B$125) -> 0.003057 | D54: =_xlfn.XLOOKUP('3_Parameters'!$B54,'2_Data'!$A$25:$A$125,'2_Data'!$C$25:$C$125) -> 0.001911 | E54: =(C54*share_male)+(D54*(1-share_male)) -> 0.00289656
...

Sheet 4_Transitions
A1: Transition_Probabilities: Azathioprine (standard care) | J1: Azathioprine: “Counts from 2_Data (cav, statemax) ÷ row total. converted from a 1.65-year gap to annual
A3: from_state | B3: to_1 | C3: to_2 | D3: to_3 | E3: to_4
A4: from_1 | B4: =1-SUM(C4:E4) -> 0.86784471 | C4: =1-(1-'2_Data'!C14/'2_Data'!$F14)^(1/mean_gap) -> 0.06744388 | D4: =1-(1-'2_Data'!D14/'2_Data'!$F14)^(1/mean_gap) -> 0.014327073 | E4: =1-(1-'2_Data'!E14/'2_Data'!$F14)^(1/mean_gap) -> 0.05038434
A5: from_2 | B5: =1-(1-'2_Data'!B15/'2_Data'!$F15)^(1/mean_gap) -> 0 | C5: =1-SUM(B5,D5,E5) -> 0.80291483 | D5: =1-(1-'2_Data'!D15/'2_Data'!$F15)^(1/mean_gap) -> 0.1015722 | E5: =1-(1-'2_Data'!E15/'2_Data'!$F15)^(1/mean_gap) -> 0.095512964
A6: from_3 | B6: =1-(1-'2_Data'!B16/'2_Data'!$F16)^(1/mean_gap) -> 0 | C6: =1-(1-'2_Data'!C16/'2_Data'!$F16)^(1/mean_gap) -> 0 | D6: =1-SUM(B6,C6,E6) -> 0.79836449 | E6: =1-(1-'2_Data'!E16/'2_Data'!$F16)^(1/mean_gap) -> 0.20163551
A7: from_4 | B7: 0 | C7: 0 | D7: 0 | E7: =1-SUM(B7:D7) -> 1
A10: Transition_Probabilities: Everolimus | J10: Everolimus: “1→2 and 1→3 × RR (3_Parameters). Other cells as azathioprine.
A12: from_state | B12: to_1 | C12: to_2 | D12: to_3 | E12: to_4
A13: from_1 | B13: =1-SUM(C13:E13) -> 0.89432735 | C13: {=Az_12*RR} -> 0.04560126 | D13: =Az_13*RR -> 0.0096870549 | E13: =Az_14 -> 0.05038434
A14: from_2 | B14: =Az_21 -> 0 | C14: =1-SUM(B14,E14,D14) -> 0.80291483 | D14: =Az_23 -> 0.1015722 | E14: =Az_24 -> 0.095512964
A15: from_3 | B15: =Az_31 -> 0 | C15: =Az_32 -> 0 | D15: =1-SUM(B15:C15,ev_34) -> 0.79836449 | E15: =Az_34 -> 0.20163551
A16: from_4 | B16: =Az_41 -> 0 | C16: =Az_42 -> 0 | D16: =Az_43 -> 0 | E16: =1-SUM(B16:D16) -> 1

Sheet 5_Markov_SC
A1: Markov trace: azathioprine (standard care)
A2: Cohort of 1,000 starting in state 1 at age 47. Annual cycles, 30-year horizon. Costs and QALYs discounted at 3.5% with half-cycle correction. Results per patient in row 38.
A4: 1. State membership | L4: 2. Costs (£) | T4: 3. QALYs | Z4: 4. Adjustments
A5: Cycle | B5: Age | C5: qx (ONS) | D5: ONS check | E5: S1_ | F5: S2 | G5: S3 | H5: Dead | I5: Checksum | J5: Alive | L5: Cost S1 | M5: Cost S2 | N5: Cost S3 | O5: Cost of Death | P5: Total state cost | Q5: Drug cost | R5: Total cost | T5: QALY S1 | U5: QALY S2 | V5: QALY S3 | W5: QALY Dead | X5: Total QALYs | Z5: Half-cycle weight | AA5: Discount factor
A6: 1 | B6: =ROUND(age_start,0)+(A6-1) -> 47 | C6: =_xlfn.XLOOKUP(B6,qx_bg[Age],qx_bg[qx weighted]) -> 0.00269032 | D6: =C6<Az_14 -> TRUE | E6: =n_cohort -> 1000 | F6: 0 | G6: 0 | H6: 0 | I6: =ROUND(SUM(E6:H6),5) -> 1000 | J6: =SUM(E6:G6) -> 1000 | L6: =E6*C_1 -> 2497000 | M6: =F6*C_2 -> 0 | N6: =G6*C_3 -> 0 | O6: =H6*C_4 -> 0 | P6: =SUM(L6:O6) -> 2497000 | Q6: =J6*c_aza -> 27375 | R6: =P6+Q6 -> 2524375 | T6: =E6*u_1 -> 760 | U6: =F6*u_2 -> 0 | V6: =G6*u_3 -> 0 | W6: =H6*u_4 -> 0 | X6: =SUM(T6:W6) -> 760 | Z6: =IF(OR(A6=1,A6=horizon+1),0.5,1) -> 0.5 | AA6: =1/(1+disc)^(A6-1) -> 1
A7: 2 | B7: =ROUND(age_start,0)+(A7-1) -> 48 | C7: =_xlfn.XLOOKUP(B7,qx_bg[Age],qx_bg[qx weighted]) -> 0.00289656 | D7: =C7<Az_14 -> TRUE | E7: {=MMULT(E6:H6,'4_Transitions'!$B$4:$E$7)} -> 867.84471 | F7: 67.44388 | G7: 14.327073 | H7: 50.38434 | I7: =ROUND(SUM(E7:H7),5) -> 1000 | J7: =SUM(E7:G7) -> 949.61566 | L7: =E7*C_1 -> 2167008.2 | M7: =F7*C_2 -> 195789.58 | N7: =G7*C_3 -> 51312.411 | O7: =H7*C_4 -> 0 | P7: =SUM(L7:O7) -> 2414110.2 | Q7: =J7*c_aza -> 25995.729 | R7: =P7+Q7 -> 2440106 | T7: =E7*u_1 -> 659.56198 | U7: =F7*u_2 -> 47.885155 | V7: =G7*u_3 -> 8.7395144 | W7: =H7*u_4 -> 0 | X7: =SUM(T7:W7) -> 716.18665 | Z7: =IF(OR(A7=1,A7=horizon+1),0.5,1) -> 1 | AA7: =1/(1+disc)^(A7-1) -> 0.96618357
A8: 3 | B8: =ROUND(age_start,0)+(A8-1) -> 49 | C8: =_xlfn.XLOOKUP(B8,qx_bg[Age],qx_bg[qx weighted]) -> 0.00320766 | D8: =C8<Az_14 -> TRUE | E8: {=MMULT(E7:H7,'4_Transitions'!$B$4:$E$7)} -> 753.15444 | F8: 112.68251 | G8: 30.722324 | H8: 103.44074 | I8: =ROUND(SUM(E8:H8),5) -> 1000 | J8: =SUM(E8:G8) -> 896.55926 | L8: =E8*C_1 -> 1880626.6 | M8: =F8*C_2 -> 327117.31 | N8: =G8*C_3 -> 110032 | O8: =H8*C_4 -> 0 | P8: =SUM(L8:O8) -> 2317775.9 | Q8: =J8*c_aza -> 24543.31 | R8: =P8+Q8 -> 2342319.3 | T8: =E8*u_1 -> 572.39737 | U8: =F8*u_2 -> 80.004579 | V8: =G8*u_3 -> 18.740618 | W8: =H8*u_4 -> 0 | X8: =SUM(T8:W8) -> 671.14257 | Z8: =IF(OR(A8=1,A8=horizon+1),0.5,1) -> 1 | AA8: =1/(1+disc)^(A8-1) -> 0.9335107
A9: 4 | B9: =ROUND(age_start,0)+(A9-1) -> 50 | C9: =_xlfn.XLOOKUP(B9,qx_bg[Age],qx_bg[qx weighted]) -> 0.00352242 | D9: =C9<Az_14 -> TRUE | E9: {=MMULT(E8:H8,'4_Transitions'!$B$4:$E$7)} -> 653.62109 | F9: 141.27011 | G9: 46.763521 | H9: 158.34528 | I9: =ROUND(SUM(E9:H9),5) -> 1000 | J9: =SUM(E9:G9) -> 841.65472 | L9: =E9*C_1 -> 1632091.9 | M9: =F9*C_2 -> 410107.14 | N9: =G9*C_3 -> 167483.55 | O9: =H9*C_4 -> 0 | P9: =SUM(L9:O9) -> 2209682.5 | Q9: =J9*c_aza -> 23040.298 | R9: =P9+Q9 -> 2232722.8 | T9: =E9*u_1 -> 496.75203 | U9: =F9*u_2 -> 100.30178 | V9: =G9*u_3 -> 28.525748 | W9: =H9*u_4 -> 0 | X9: =SUM(T9:W9) -> 625.57956 | Z9: =IF(OR(A9=1,A9=horizon+1),0.5,1) -> 1 | AA9: =1/(1+disc)^(A9-1) -> 0.90194271
A10: 5 | B10: =ROUND(age_start,0)+(A10-1) -> 51 | C10: =_xlfn.XLOOKUP(B10,qx_bg[Age],qx_bg[qx weighted]) -> 0.00380464 | D10: =C10<Az_14 -> TRUE | E10: {=MMULT(E9:H9,'4_Transitions'!$B$4:$E$7)} -> 567.2416 | F10: 157.51061 | G10: 61.047928 | H10: 214.19986 | I10: =ROUND(SUM(E10:H10),5) -> 1000 | J10: =SUM(E10:G10) -> 785.80014 | L10: =E10*C_1 -> 1416402.3 | M10: =F10*C_2 -> 457253.3 | N10: =G10*C_3 -> 218643.15 | O10: =H10*C_4 -> 0 | P10: =SUM(L10:O10) -> 2092298.7 | Q10: =J10*c_aza -> 21511.279 | R10: =P10+Q10 -> 2113810 | T10: =E10*u_1 -> 431.10362 | U10: =F10*u_2 -> 111.83253 | V10: =G10*u_3 -> 37.239236 | W10: =H10*u_4 -> 0 | X10: =SUM(T10:W10) -> 580.17539 | Z10: =IF(OR(A10=1,A10=horizon+1),0.5,1) -> 1 | AA10: =1/(1+disc)^(A10-1) -> 0.87144223
A11: 6 | B11: =ROUND(age_start,0)+(A11-1) -> 52 | C11: =_xlfn.XLOOKUP(B11,qx_bg[Age],qx_bg[qx weighted]) -> 0.00404826 | D11: =C11<Az_14 -> TRUE | E11: {=MMULT(E10:H10,'4_Transitions'!$B$4:$E$7)} -> 492.27762 | F11: 164.72458 | G11: 72.864109 | H11: 270.13369 | I11: =ROUND(SUM(E11:H11),5) -> 1000 | J11: =SUM(E11:G11) -> 729.86631 | L11: =E11*C_1 -> 1229217.2 | M11: =F11*C_2 -> 478195.46 | N11: =G11*C_3 -> 260962.81 | O11: =H11*C_4 -> 0 | P11: =SUM(L11:O11) -> 1968375.5 | Q11: =J11*c_aza -> 19980.09 | R11: =P11+Q11 -> 1988355.6 | T11: =E11*u_1 -> 374.13099 | U11: =F11*u_2 -> 116.95445 | V11: =G11*u_3 -> 44.447107 | W11: =H11*u_4 -> 0 | X11: =SUM(T11:W11) -> 535.53255 | Z11: =IF(OR(A11=1,A11=horizon+1),0.5,1) -> 1 | AA11: =1/(1+disc)^(A11-1) -> 0.84197317
A12: 7 | B12: =ROUND(age_start,0)+(A12-1) -> 53 | C12: =_xlfn.XLOOKUP(B12,qx_bg[Age],qx_bg[qx weighted]) -> 0.00431134 | D12: =C12<Az_14 -> TRUE | E12: {=MMULT(E11:H11,'4_Transitions'!$B$4:$E$7)} -> 427.22053 | F12: 165.46092 | G12: 81.956453 | H12: 325.3621 | I12: =ROUND(SUM(E12:H12),5) -> 1000 | J12: =SUM(E12:G12) -> 674.6379 | L12: =E12*C_1 -> 1066769.7 | M12: =F12*C_2 -> 480333.06 | N12: =G12*C_3 -> 293527.04 | O12: =H12*C_4 -> 0 | P12: =SUM(L12:O12) -> 1840629.8 | Q12: =J12*c_aza -> 18468.213 | R12: =P12+Q12 -> 1859098 | T12: =E12*u_1 -> 324.6876 | U12: =F12*u_2 -> 117.47725 | V12: =G12*u_3 -> 49.993436 | W12: =H12*u_4 -> 0 | X12: =SUM(T12:W12) -> 492.15829 | Z12: =IF(OR(A12=1,A12=horizon+1),0.5,1) -> 1 | AA12: =1/(1+disc)^(A12-1) -> 0.81350064
A13: 8 | B13: =ROUND(age_start,0)+(A13-1) -> 54 | C13: =_xlfn.XLOOKUP(B13,qx_bg[Age],qx_bg[qx weighted]) -> 0.0046732 | D13: =C13<Az_14 -> TRUE | E13: {=MMULT(E12:H12,'4_Transitions'!$B$4:$E$7)} -> 370.76108 | F13: 161.66444 | G13: 88.358172 | H13: 379.21631 | I13: =ROUND(SUM(E13:H13),5) -> 1000 | J13: =SUM(E13:G13) -> 620.78369 | L13: =E13*C_1 -> 925790.41 | M13: =F13*C_2 -> 469311.86 | N13: =G13*C_3 -> 316454.79 | O13: =H13*C_4 -> 0 | P13: =SUM(L13:O13) -> 1711557.1 | Q13: =J13*c_aza -> 16993.953 | R13: =P13+Q13 -> 1728551 | T13: =E13*u_1 -> 281.77842 | U13: =F13*u_2 -> 114.78175 | V13: =G13*u_3 -> 53.898485 | W13: =H13*u_4 -> 0 | X13: =SUM(T13:W13) -> 450.45865 | Z13: =IF(OR(A13=1,A13=horizon+1),0.5,1) -> 1 | AA13: =1/(1+disc)^(A13-1) -> 0.78599096
A14: 9 | B14: =ROUND(age_start,0)+(A14-1) -> 55 | C14: =_xlfn.XLOOKUP(B14,qx_bg[Age],qx_bg[qx weighted]) -> 0.00504714 | D14: =C14<Az_14 -> TRUE | E14: {=MMULT(E13:H13,'4_Transitions'!$B$4:$E$7)} -> 321.76304 | F14: 154.80834 | G14: 92.27456 | H14: 431.15406 | I14: =ROUND(SUM(E14:H14),5) -> 1000 | J14: =SUM(E14:G14) -> 568.84594 | L14: =E14*C_1 -> 803442.3 | M14: =F14*C_2 -> 449408.61 | N14: =G14*C_3 -> 330481.34 | O14: =H14*C_4 -> 0 | P14: =SUM(L14:O14) -> 1583332.3 | Q14: =J14*c_aza -> 15572.158 | R14: =P14+Q14 -> 1598904.4 | T14: =E14*u_1 -> 244.53991 | U14: =F14*u_2 -> 109.91392 | V14: =G14*u_3 -> 56.287482 | W14: =H14*u_4 -> 0 | X14: =SUM(T14:W14) -> 410.74131 | Z14: =IF(OR(A14=1,A14=horizon+1),0.5,1) -> 1 | AA14: =1/(1+disc)^(A14-1) -> 0.75941156
A15: 10 | B15: =ROUND(age_start,0)+(A15-1) -> 56 | C15: =_xlfn.XLOOKUP(B15,qx_bg[Age],qx_bg[qx weighted]) -> 0.00545566 | D15: =C15<Az_14 -> TRUE | E15: {=MMULT(E14:H14,'4_Transitions'!$B$4:$E$7)} -> 279.24035 | F15: 145.99886 | G15: 94.002879 | H15: 480.75791 | I15: =ROUND(SUM(E15:H15),5) -> 1000 | J15: =SUM(E15:G15) -> 519.24209 | L15: =E15*C_1 -> 697263.15 | M15: =F15*C_2 -> 423834.69 | N15: =G15*C_3 -> 336671.31 | O15: =H15*C_4 -> 0 | P15: =SUM(L15:O15) -> 1457769.2 | Q15: =J15*c_aza -> 14214.252 | R15: =P15+Q15 -> 1471983.4 | T15: =E15*u_1 -> 212.22266 | U15: =F15*u_2 -> 103.65919 | V15: =G15*u_3 -> 57.341756 | W15: =H15*u_4 -> 0 | X15: =SUM(T15:W15) -> 373.22361 | Z15: =IF(OR(A15=1,A15=horizon+1),0.5,1) -> 1 | AA15: =1/(1+disc)^(A15-1) -> 0.73373097
A16: 11 | B16: =ROUND(age_start,0)+(A16-1) -> 57 | C16: =_xlfn.XLOOKUP(B16,qx_bg[Age],qx_bg[qx weighted]) -> 0.00594696 | D16: =C16<Az_14 -> TRUE | E16: {=MMULT(E15:H15,'4_Transitions'!$B$4:$E$7)} -> 242.33726 | F16: 136.0577 | G16: 93.878683 | H16: 527.72636 | I16: =ROUND(SUM(E16:H16),5) -> 1000 | J16: =SUM(E16:G16) -> 472.27364 | L16: =E16*C_1 -> 605116.13 | M16: =F16*C_2 -> 394975.51 | N16: =G16*C_3 -> 336226.5 | O16: =H16*C_4 -> 0 | P16: =SUM(L16:O16) -> 1336318.2 | Q16: =J16*c_aza -> 12928.491 | R16: =P16+Q16 -> 1349246.6 | T16: =E16*u_1 -> 184.17632 | U16: =F16*u_2 -> 96.600969 | V16: =G16*u_3 -> 57.265997 | W16: =H16*u_4 -> 0 | X16: =SUM(T16:W16) -> 338.04328 | Z16: =IF(OR(A16=1,A16=horizon+1),0.5,1) -> 1 | AA16: =1/(1+disc)^(A16-1) -> 0.70891881
A17: 12 | B17: =ROUND(age_start,0)+(A17-1) -> 58 | C17: =_xlfn.XLOOKUP(B17,qx_bg[Age],qx_bg[qx weighted]) -> 0.0063892 | D17: =C17<Az_14 -> TRUE | E17: {=MMULT(E16:H16,'4_Transitions'!$B$4:$E$7)} -> 210.31111 | F17: 125.58691 | G17: 92.241071 | H17: 571.86091 | I17: =ROUND(SUM(E17:H17),5) -> 1000 | J17: =SUM(E17:G17) -> 428.13909 | L17: =E17*C_1 -> 525146.83 | M17: =F17*C_2 -> 364578.81 | N17: =G17*C_3 -> 330361.4 | O17: =H17*C_4 -> 0 | P17: =SUM(L17:O17) -> 1220087 | Q17: =J17*c_aza -> 11720.308 | R17: =P17+Q17 -> 1231807.3 | T17: =E17*u_1 -> 159.83644 | U17: =F17*u_2 -> 89.166708 | V17: =G17*u_3 -> 56.267053 | W17: =H17*u_4 -> 0 | X17: =SUM(T17:W17) -> 305.2702 | Z17: =IF(OR(A17=1,A17=horizon+1),0.5,1) -> 1 | AA17: =1/(1+disc)^(A17-1) -> 0.68494571
A18: 13 | B18: =ROUND(age_start,0)+(A18-1) -> 59 | C18: =_xlfn.XLOOKUP(B18,qx_bg[Age],qx_bg[qx weighted]) -> 0.0068706 | D18: =C18<Az_14 -> TRUE | E18: {=MMULT(E17:H17,'4_Transitions'!$B$4:$E$7)} -> 182.51738 | F18: 115.01979 | G18: 89.411277 | H18: 613.05155 | I18: =ROUND(SUM(E18:H18),5) -> 1000 | J18: =SUM(E18:G18) -> 386.94845 | L18: =E18*C_1 -> 455745.9 | M18: =F18*C_2 -> 333902.46 | N18: =G18*C_3 -> 320226.49 | O18: =H18*C_4 -> 0 | P18: =SUM(L18:O18) -> 1109874.8 | Q18: =J18*c_aza -> 10592.714 | R18: =P18+Q18 -> 1120467.6 | T18: =E18*u_1 -> 138.71321 | U18: =F18*u_2 -> 81.664053 | V18: =G18*u_3 -> 54.540879 | W18: =H18*u_4 -> 0 | X18: =SUM(T18:W18) -> 274.91814 | Z18: =IF(OR(A18=1,A18=horizon+1),0.5,1) -> 1 | AA18: =1/(1+disc)^(A18-1) -> 0.6617833
... A36: 31 | B36: =ROUND(age_start,0)+(A36-1) -> 77 | C36: =_xlfn.XLOOKUP(B36,qx_bg[Age],qx_bg[qx weighted]) -> 0.0356048 | D36: =C36<Az_14 -> TRUE | E36: {=MMULT(E35:H35,'4_Transitions'!$B$4:$E$7)} -> 14.231824 | F36: 13.348753 | G36: 17.519436 | H36: 954.89999 | I36: =ROUND(SUM(E36:H36),5) -> 1000 | J36: =SUM(E36:G36) -> 45.100014 | L36: =E36*C_1 -> 35536.865 | M36: =F36*C_2 -> 38751.431 | N36: =G36*C_3 -> 62745.86 | O36: =H36*C_4 -> 0 | P36: =SUM(L36:O36) -> 137034.16 | Q36: =J36*c_aza -> 1234.6129 | R36: =P36+Q36 -> 138268.77 | T36: =E36*u_1 -> 10.816186 | U36: =F36*u_2 -> 9.4776148 | V36: =G36*u_3 -> 10.686856 | W36: =H36*u_4 -> 0 | X36: =SUM(T36:W36) -> 30.980657 | Z36: =IF(OR(A36=1,A36=horizon+1),0.5,1) -> 0.5 | AA36: =1/(1+disc)^(A36-1) -> 0.35627841
I38: Life years (undiscounted) | J38: =SUMPRODUCT(J6:J36,$Z$6:$Z$36)/n_cohort -> 11.161401 | K38: Per patient (discounted) | L38: =SUMPRODUCT(L6:L36,$Z$6:$Z$36,$AA$6:$AA$36)/n_cohort -> 14140.477 | M38: =SUMPRODUCT(M6:M36,$Z$6:$Z$36,$AA$6:$AA$36)/n_cohort -> 5142.357 | N38: =SUMPRODUCT(N6:N36,$Z$6:$Z$36,$AA$6:$AA$36)/n_cohort -> 3968.7592 | O38: =SUMPRODUCT(O6:O36,$Z$6:$Z$36,$AA$6:$AA$36)/n_cohort -> 0 | P38: =SUMPRODUCT(P6:P36,$Z$6:$Z$36,$AA$6:$AA$36)/n_cohort -> 23251.594 | Q38: =SUMPRODUCT(Q6:Q36,$Z$6:$Z$36,$AA$6:$AA$36)/n_cohort -> 233.85116 | R38: =SUMPRODUCT(R6:R36,$Z$6:$Z$36,$AA$6:$AA$36)/n_cohort -> 23485.445 | T38: =SUMPRODUCT(T6:T36,$Z$6:$Z$36,$AA$6:$AA$36)/n_cohort -> 4.3038698 | U38: =SUMPRODUCT(U6:U36,$Z$6:$Z$36,$AA$6:$AA$36)/n_cohort -> 1.2576898 | V38: =SUMPRODUCT(V6:V36,$Z$6:$Z$36,$AA$6:$AA$36)/n_cohort -> 0.67595787 | W38: =SUMPRODUCT(W6:W36,$Z$6:$Z$36,$AA$6:$AA$36)/n_cohort -> 0 | X38: =SUMPRODUCT(X6:X36,$Z$6:$Z$36,$AA$6:$AA$36)/n_cohort -> 6.2375174
I39: Limitation: 4.5% of the cohort is still alive at 30 years, so lifetime costs, QALYs and life years are slightly underestimated (life years by about 3%).

Sheet 6_Markov_EVE
A1: Markov trace: everolimus
A2: Cohort of 1,000 starting in state 1 at age 47. Annual cycles, 30-year horizon. Costs and QALYs discounted at 3.5% with half-cycle correction. Results per patient in row 38.
A4: 1. State membership | L4: 2. Costs (£) | T4: 3. QALYs | Z4: 4. Adjustments
A5: Cycle | B5: Age | C5: qx (ONS) | D5: ONS check | E5: S1 | F5: S2 | G5: S3 | H5: Dead | I5: Checksum | J5: Alive | L5: Cost S1 | M5: Cost S2 | N5: Cost S3 | O5: Cost of Death | P5: Total state cost | Q5: Drug cost | R5: Total cost | T5: QALY S1 | U5: QALY S2 | V5: QALY S3 | W5: QALY Dead | X5: Total QALYs | Z5: Half-cycle weight | AA5: Discount factor
A6: 1 | B6: =ROUND(age_start,0)+(A6-1) -> 47 | C6: =_xlfn.XLOOKUP(B6,qx_bg[Age],qx_bg[qx weighted]) -> 0.00269032 | D6: =C6<ev_14 -> TRUE | E6: =n_cohort -> 1000 | F6: 0 | G6: 0 | H6: 0 | I6: =ROUND(SUM(E6:H6),5) -> 1000 | J6: =SUM(E6:G6) -> 1000 | L6: =E6*C_1 -> 2497000 | M6: =F6*C_2 -> 0 | N6: =G6*C_3 -> 0 | O6: =H6*C_4 -> 0 | P6: =SUM(L6:O6) -> 2497000 | Q6: =J6*c_eve -> 5420250 | R6: =P6+Q6 -> 7917250 | T6: =E6*u_1 -> 760 | U6: =F6*u_2 -> 0 | V6: =G6*u_3 -> 0 | W6: =H6*u_4 -> 0 | X6: =SUM(T6:W6) -> 760 | Z6: =IF(OR(A6=1,A6=horizon+1),0.5,1) -> 0.5 | AA6: =1/(1+disc)^(A6-1) -> 1
A7: 2 | B7: =ROUND(age_start,0)+(A7-1) -> 48 | C7: =_xlfn.XLOOKUP(B7,qx_bg[Age],qx_bg[qx weighted]) -> 0.00289656 | D7: =C7<ev_14 -> TRUE | E7: {=MMULT(E6:H6,'4_Transitions'!$B$13:$E$16)} -> 894.32735 | F7: 45.60126 | G7: 9.6870549 | H7: 50.38434 | I7: =ROUND(SUM(E7:H7),5) -> 1000 | J7: =SUM(E7:G7) -> 949.61566 | L7: =E7*C_1 -> 2233135.4 | M7: =F7*C_2 -> 132380.46 | N7: =G7*C_3 -> 34694.187 | O7: =H7*C_4 -> 0 | P7: =SUM(L7:O7) -> 2400210 | Q7: =J7*c_eve -> 5147154.3 | R7: =P7+Q7 -> 7547364.3 | T7: =E7*u_1 -> 679.68878 | U7: =F7*u_2 -> 32.376894 | V7: =G7*u_3 -> 5.9091035 | W7: =H7*u_4 -> 0 | X7: =SUM(T7:W7) -> 717.97478 | Z7: =IF(OR(A7=1,A7=horizon+1),0.5,1) -> 1 | AA7: =1/(1+disc)^(A7-1) -> 0.96618357
A8: 3 | B8: =ROUND(age_start,0)+(A8-1) -> 49 | C8: =_xlfn.XLOOKUP(B8,qx_bg[Age],qx_bg[qx weighted]) -> 0.00320766 | D8: =C8<ev_14 -> TRUE | E8: {=MMULT(E7:H7,'4_Transitions'!$B$13:$E$16)} -> 799.8214 | F8: 77.396381 | G8: 21.029019 | H8: 101.7532 | I8: =ROUND(SUM(E8:H8),5) -> 1000 | J8: =SUM(E8:G8) -> 898.2468 | L8: =E8*C_1 -> 1997154 | M8: =F8*C_2 -> 224681.69 | N8: =G8*C_3 -> 75315.432 | O8: =H8*C_4 -> 0 | P8: =SUM(L8:O8) -> 2297151.2 | Q8: =J8*c_eve -> 4868722.2 | R8: =P8+Q8 -> 7165873.4 | T8: =E8*u_1 -> 607.86426 | U8: =F8*u_2 -> 54.951431 | V8: =G8*u_3 -> 12.827702 | W8: =H8*u_4 -> 0 | X8: =SUM(T8:W8) -> 675.6434 | Z8: =IF(OR(A8=1,A8=horizon+1),0.5,1) -> 1 | AA8: =1/(1+disc)^(A8-1) -> 0.9335107
A9: 4 | B9: =ROUND(age_start,0)+(A9-1) -> 50 | C9: =_xlfn.XLOOKUP(B9,qx_bg[Age],qx_bg[qx weighted]) -> 0.00352242 | D9: =C9<ev_14 -> TRUE | E9: {=MMULT(E8:H8,'4_Transitions'!$B$13:$E$16)} -> 715.30215 | F9: 98.615566 | G9: 32.398057 | H9: 153.68423 | I9: =ROUND(SUM(E9:H9),5) -> 1000 | J9: =SUM(E9:G9) -> 846.31577 | L9: =E9*C_1 -> 1786109.5 | M9: =F9*C_2 -> 286280.99 | N9: =G9*C_3 -> 116033.64 | O9: =H9*C_4 -> 0 | P9: =SUM(L9:O9) -> 2188424.1 | Q9: =J9*c_eve -> 4587243.1 | R9: =P9+Q9 -> 6775667.2 | T9: =E9*u_1 -> 543.62963 | U9: =F9*u_2 -> 70.017052 | V9: =G9*u_3 -> 19.762815 | W9: =H9*u_4 -> 0 | X9: =SUM(T9:W9) -> 633.4095 | Z9: =IF(OR(A9=1,A9=horizon+1),0.5,1) -> 1 | AA9: =1/(1+disc)^(A9-1) -> 0.90194271
A10: 5 | B10: =ROUND(age_start,0)+(A10-1) -> 51 | C10: =_xlfn.XLOOKUP(B10,qx_bg[Age],qx_bg[qx weighted]) -> 0.00380464 | D10: =C10<ev_14 -> TRUE | E10: {=MMULT(E9:H9,'4_Transitions'!$B$13:$E$16)} -> 639.71427 | F10: 111.79858 | G10: 42.811229 | H10: 205.67592 | I10: =ROUND(SUM(E10:H10),5) -> 1000 | J10: =SUM(E10:G10) -> 794.32408 | L10: =E10*C_1 -> 1597366.5 | M10: =F10*C_2 -> 324551.28 | N10: =G10*C_3 -> 153328.42 | O10: =H10*C_4 -> 0 | P10: =SUM(L10:O10) -> 2075246.2 | Q10: =J10*c_eve -> 4305435.1 | R10: =P10+Q10 -> 6380681.3 | T10: =E10*u_1 -> 486.18285 | U10: =F10*u_2 -> 79.376991 | V10: =G10*u_3 -> 26.11485 | W10: =H10*u_4 -> 0 | X10: =SUM(T10:W10) -> 591.67469 | Z10: =IF(OR(A10=1,A10=horizon+1),0.5,1) -> 1 | AA10: =1/(1+disc)^(A10-1) -> 0.87144223
A11: 6 | B11: =ROUND(age_start,0)+(A11-1) -> 52 | C11: =_xlfn.XLOOKUP(B11,qx_bg[Age],qx_bg[qx weighted]) -> 0.00404826 | D11: =C11<ev_14 -> TRUE | E11: {=MMULT(E10:H10,'4_Transitions'!$B$13:$E$16)} -> 572.11397 | F11: 118.93651 | G11: 51.73154 | H11: 257.21798 | I11: =ROUND(SUM(E11:H11),5) -> 1000 | J11: =SUM(E11:G11) -> 742.78202 | L11: =E11*C_1 -> 1428568.6 | M11: =F11*C_2 -> 345272.7 | N11: =G11*C_3 -> 185276.51 | O11: =H11*C_4 -> 0 | P11: =SUM(L11:O11) -> 1959117.8 | Q11: =J11*c_eve -> 4026064.3 | R11: =P11+Q11 -> 5985182 | T11: =E11*u_1 -> 434.80661 | U11: =F11*u_2 -> 84.444925 | V11: =G11*u_3 -> 31.55624 | W11: =H11*u_4 -> 0 | X11: =SUM(T11:W11) -> 550.80778 | Z11: =IF(OR(A11=1,A11=horizon+1),0.5,1) -> 1 | AA11: =1/(1+disc)^(A11-1) -> 0.84197317
A12: 7 | B12: =ROUND(age_start,0)+(A12-1) -> 53 | C12: =_xlfn.XLOOKUP(B12,qx_bg[Age],qx_bg[qx weighted]) -> 0.00431134 | D12: =C12<ev_14 -> TRUE | E12: {=MMULT(E11:H11,'4_Transitions'!$B$13:$E$16)} -> 511.65716 | F12: 121.58501 | G12: 58.923368 | H12: 307.83446 | I12: =ROUND(SUM(E12:H12),5) -> 1000 | J12: =SUM(E12:G12) -> 692.16554 | L12: =E12*C_1 -> 1277607.9 | M12: =F12*C_2 -> 352961.28 | N12: =G12*C_3 -> 211034.04 | O12: =H12*C_4 -> 0 | P12: =SUM(L12:O12) -> 1841603.3 | Q12: =J12*c_eve -> 3751710.3 | R12: =P12+Q12 -> 5593313.5 | T12: =E12*u_1 -> 388.85945 | U12: =F12*u_2 -> 86.325356 | V12: =G12*u_3 -> 35.943254 | W12: =H12*u_4 -> 0 | X12: =SUM(T12:W12) -> 511.12806 | Z12: =IF(OR(A12=1,A12=horizon+1),0.5,1) -> 1 | AA12: =1/(1+disc)^(A12-1) -> 0.81350064
A13: 8 | B13: =ROUND(age_start,0)+(A13-1) -> 54 | C13: =_xlfn.XLOOKUP(B13,qx_bg[Age],qx_bg[qx weighted]) -> 0.0046732 | D13: =C13<ev_14 -> TRUE | E13: {=MMULT(E12:H12,'4_Transitions'!$B$13:$E$16)} -> 457.58899 | F13: 120.95462 | G13: 64.348433 | H13: 357.10796 | I13: =ROUND(SUM(E13:H13),5) -> 1000 | J13: =SUM(E13:G13) -> 642.89204 | L13: =E13*C_1 -> 1142599.7 | M13: =F13*C_2 -> 351131.26 | N13: =G13*C_3 -> 230463.91 | O13: =H13*C_4 -> 0 | P13: =SUM(L13:O13) -> 1724194.9 | Q13: =J13*c_eve -> 3484635.6 | R13: =P13+Q13 -> 5208830.5 | T13: =E13*u_1 -> 347.76764 | U13: =F13*u_2 -> 85.877779 | V13: =G13*u_3 -> 39.252544 | W13: =H13*u_4 -> 0 | X13: =SUM(T13:W13) -> 472.89796 | Z13: =IF(OR(A13=1,A13=horizon+1),0.5,1) -> 1 | AA13: =1/(1+disc)^(A13-1) -> 0.78599096
A14: 9 | B14: =ROUND(age_start,0)+(A14-1) -> 55 | C14: =_xlfn.XLOOKUP(B14,qx_bg[Age],qx_bg[qx weighted]) -> 0.00504714 | D14: =C14<ev_14 -> TRUE | E14: {=MMULT(E13:H13,'4_Transitions'!$B$13:$E$16)} -> 409.23435 | F14: 117.98289 | G14: 68.09182 | H14: 404.69094 | I14: =ROUND(SUM(E14:H14),5) -> 1000 | J14: =SUM(E14:G14) -> 595.30906 | L14: =E14*C_1 -> 1021858.2 | M14: =F14*C_2 -> 342504.33 | N14: =G14*C_3 -> 243870.85 | O14: =H14*C_4 -> 0 | P14: =SUM(L14:O14) -> 1608233.4 | Q14: =J14*c_eve -> 3226723.9 | R14: =P14+Q14 -> 4834957.3 | T14: =E14*u_1 -> 311.01811 | U14: =F14*u_2 -> 83.767853 | V14: =G14*u_3 -> 41.53601 | W14: =H14*u_4 -> 0 | X14: =SUM(T14:W14) -> 436.32197 | Z14: =IF(OR(A14=1,A14=horizon+1),0.5,1) -> 1 | AA14: =1/(1+disc)^(A14-1) -> 0.75941156
A15: 10 | B15: =ROUND(age_start,0)+(A15-1) -> 56 | C15: =_xlfn.XLOOKUP(B15,qx_bg[Age],qx_bg[qx weighted]) -> 0.00545566 | D15: =C15<ev_14 -> TRUE | E15: {=MMULT(E14:H14,'4_Transitions'!$B$13:$E$16)} -> 365.98947 | F15: 113.39182 | G15: 70.310149 | H15: 450.30857 | I15: =ROUND(SUM(E15:H15),5) -> 1000 | J15: =SUM(E15:G15) -> 549.69143 | L15: =E15*C_1 -> 913875.71 | M15: =F15*C_2 -> 329176.44 | N15: =G15*C_3 -> 251815.8 | O15: =H15*C_4 -> 0 | P15: =SUM(L15:O15) -> 1494867.9 | Q15: =J15*c_eve -> 2979465 | R15: =P15+Q15 -> 4474332.9 | T15: =E15*u_1 -> 278.152 | U15: =F15*u_2 -> 80.508189 | V15: =G15*u_3 -> 42.889191 | W15: =H15*u_4 -> 0 | X15: =SUM(T15:W15) -> 401.54938 | Z15: =IF(OR(A15=1,A15=horizon+1),0.5,1) -> 1 | AA15: =1/(1+disc)^(A15-1) -> 0.73373097
A16: 11 | B16: =ROUND(age_start,0)+(A16-1) -> 57 | C16: =_xlfn.XLOOKUP(B16,qx_bg[Age],qx_bg[qx weighted]) -> 0.00594696 | D16: =C16<ev_14 -> TRUE | E16: {=MMULT(E15:H15,'4_Transitions'!$B$13:$E$16)} -> 327.31439 | F16: 107.73355 | G16: 71.195943 | H16: 493.75612 | I16: =ROUND(SUM(E16:H16),5) -> 1000 | J16: =SUM(E16:G16) -> 506.24388 | L16: =E16*C_1 -> 817304.03 | M16: =F16*C_2 -> 312750.5 | N16: =G16*C_3 -> 254988.27 | O16: =H16*C_4 -> 0 | P16: =SUM(L16:O16) -> 1385042.8 | Q16: =J16*c_eve -> 2743968.4 | R16: =P16+Q16 -> 4129011.2 | T16: =E16*u_1 -> 248.75894 | U16: =F16*u_2 -> 76.490822 | V16: =G16*u_3 -> 43.429525 | W16: =H16*u_4 -> 0 | X16: =SUM(T16:W16) -> 368.67928 | Z16: =IF(OR(A16=1,A16=horizon+1),0.5,1) -> 1 | AA16: =1/(1+disc)^(A16-1) -> 0.70891881
A17: 12 | B17: =ROUND(age_start,0)+(A17-1) -> 58 | C17: =_xlfn.XLOOKUP(B17,qx_bg[Age],qx_bg[qx weighted]) -> 0.0063892 | D17: =C17<ev_14 -> TRUE | E17: {=MMULT(E16:H16,'4_Transitions'!$B$13:$E$16)} -> 292.72621 | F17: 101.42682 | G17: 70.953759 | H17: 534.89322 | I17: =ROUND(SUM(E17:H17),5) -> 1000 | J17: =SUM(E17:G17) -> 465.10678 | L17: =E17*C_1 -> 730937.35 | M17: =F17*C_2 -> 294442.04 | N17: =G17*C_3 -> 254120.89 | O17: =H17*C_4 -> 0 | P17: =SUM(L17:O17) -> 1279500.3 | Q17: =J17*c_eve -> 2520995 | R17: =P17+Q17 -> 3800495.3 | T17: =E17*u_1 -> 222.47192 | U17: =F17*u_2 -> 72.013039 | V17: =G17*u_3 -> 43.281793 | W17: =H17*u_4 -> 0 | X17: =SUM(T17:W17) -> 337.76675 | Z17: =IF(OR(A17=1,A17=horizon+1),0.5,1) -> 1 | AA17: =1/(1+disc)^(A17-1) -> 0.68494571
A18: 13 | B18: =ROUND(age_start,0)+(A18-1) -> 59 | C18: =_xlfn.XLOOKUP(B18,qx_bg[Age],qx_bg[qx weighted]) -> 0.0068706 | D18: =C18<ev_14 -> TRUE | E18: {=MMULT(E17:H17,'4_Transitions'!$B$13:$E$16)} -> 261.79305 | F18: 94.785778 | G18: 69.784761 | H18: 573.63641 | I18: =ROUND(SUM(E18:H18),5) -> 1000 | J18: =SUM(E18:G18) -> 426.36359 | L18: =E18*C_1 -> 653697.26 | M18: =F18*C_2 -> 275163.11 | N18: =G18*C_3 -> 249934.12 | O18: =H18*C_4 -> 0 | P18: =SUM(L18:O18) -> 1178794.5 | Q18: =J18*c_eve -> 2310997.3 | R18: =P18+Q18 -> 3489791.8 | T18: =E18*u_1 -> 198.96272 | U18: =F18*u_2 -> 67.297902 | V18: =G18*u_3 -> 42.568704 | W18: =H18*u_4 -> 0 | X18: =SUM(T18:W18) -> 308.82933 | Z18: =IF(OR(A18=1,A18=horizon+1),0.5,1) -> 1 | AA18: =1/(1+disc)^(A18-1) -> 0.6617833
... A36: 31 | B36: =ROUND(age_start,0)+(A36-1) -> 77 | C36: =_xlfn.XLOOKUP(B36,qx_bg[Age],qx_bg[qx weighted]) -> 0.0356048 | D36: =C36<ev_14 -> TRUE | E36: {=MMULT(E35:H35,'4_Transitions'!$B$13:$E$16)} -> 35.066732 | F36: 16.804348 | G36: 18.91321 | H36: 929.21571 | I36: =ROUND(SUM(E36:H36),5) -> 1000 | J36: =SUM(E36:G36) -> 70.78429 | L36: =E36*C_1 -> 87561.631 | M36: =F36*C_2 -> 48783.022 | N36: =G36*C_3 -> 67737.66 | O36: =H36*C_4 -> 0 | P36: =SUM(L36:O36) -> 204082.31 | Q36: =J36*c_eve -> 383668.55 | R36: =P36+Q36 -> 587750.86 | T36: =E36*u_1 -> 26.650717 | U36: =F36*u_2 -> 11.931087 | V36: =G36*u_3 -> 11.537058 | W36: =H36*u_4 -> 0 | X36: =SUM(T36:W36) -> 50.118862 | Z36: =IF(OR(A36=1,A36=horizon+1),0.5,1) -> 0.5 | AA36: =1/(1+disc)^(A36-1) -> 0.35627841
I38: Life years (undiscounted) | J38: =SUMPRODUCT(J6:J36,$Z$6:$Z$36)/n_cohort -> 12.060512 | K38: Per patient (discounted) | L38: =SUMPRODUCT(L6:L36,$Z$6:$Z$36,$AA$6:$AA$36)/n_cohort -> 16909.265 | M38: =SUMPRODUCT(M6:M36,$Z$6:$Z$36,$AA$6:$AA$36)/n_cohort -> 4075.4424 | N38: =SUMPRODUCT(N6:N36,$Z$6:$Z$36,$AA$6:$AA$36)/n_cohort -> 3125.3292 | O38: =SUMPRODUCT(O6:O36,$Z$6:$Z$36,$AA$6:$AA$36)/n_cohort -> 0 | P38: =SUMPRODUCT(P6:P36,$Z$6:$Z$36,$AA$6:$AA$36)/n_cohort -> 24110.037 | Q38: =SUMPRODUCT(Q6:Q36,$Z$6:$Z$36,$AA$6:$AA$36)/n_cohort -> 49044.245 | R38: =SUMPRODUCT(R6:R36,$Z$6:$Z$36,$AA$6:$AA$36)/n_cohort -> 73154.282 | T38: =SUMPRODUCT(T6:T36,$Z$6:$Z$36,$AA$6:$AA$36)/n_cohort -> 5.1465925 | U38: =SUMPRODUCT(U6:U36,$Z$6:$Z$36,$AA$6:$AA$36)/n_cohort -> 0.99674962 | V38: =SUMPRODUCT(V6:V36,$Z$6:$Z$36,$AA$6:$AA$36)/n_cohort -> 0.53230513 | W38: =SUMPRODUCT(W6:W36,$Z$6:$Z$36,$AA$6:$AA$36)/n_cohort -> 0 | X38: =SUMPRODUCT(X6:X36,$Z$6:$Z$36,$AA$6:$AA$36)/n_cohort -> 6.6756473
I39: Limitation: 4.5% of the cohort is still alive at 30 years, so lifetime costs, QALYs and life years are slightly underestimated (life years by about 3%).

Sheet 7_Results
A1: Results
A3: Base-case results
A5: Tx | B5: Total Costs | C5: Total QALY | D5: Life years | E5: Incremental cost | F5: Incremental QALYs | G5: ICER (£/QALY)
A6: Azathioprine | B6: =TC_disc_sc -> 23485.445 | C6: =TQ_disc_sc -> 6.2375174 | D6: =LY_aza -> 11.161401
A7: Everolimus | B7: =TC_disc_ev -> 73154.282 | C7: =TQ_disc_ev -> 6.6756473 | D7: =LY_eve -> 12.060512 | E7: =B7-B6 -> 49668.837 | F7: =C7-C6 -> 0.43812984 | G7: =E7/F7 -> 113365.56
A9: Net monetary benefit
A11: Tx | B11: NMB at £25,000 | C11: NMB at £35,000
A12: Azathioprine | B12: =Thre_LOW*C6-B6 -> 132452.49 | C12: =Thre_HIGH*C6-B6 -> 194827.67
A13: Everolimus | B13: =Thre_LOW*C7-B7 -> 93736.9 | C13: =Thre_HIGH*C7-B7 -> 160493.37
A14: Incremental NMB | B14: =B13-B12 -> -38715.591 | C14: =C13-C12 -> -34334.293
A15: Cost-effective? | B15: =IF(B14>0,"Yes","No") -> No | C15: =IF(C14>0,"Yes","No") -> No
A17: Charts

Sheet 8_DSA
A1: One-way sensitivity analysis
A3: Parameter | B3: Input cell to change | C3: Base | D3: Low | E3: High | F3: ICER at Base | G3: ICER at low | H3: ICER at high | I3: Range | J3: Low value | K3: High value
A4: PCI cost | B4: B45 | C4: 2725 | D4: 2044 | E4: 3406 | F4: 113365.56 | G4: 113402.17 | H4: 113328.96 | I4: =ABS(H4-G4) -> 73.20797 | J4: =G4-F4 -> 36.603985 | K4: =H4-F4 -> -36.603985
A5: Clinic visit cost | B5: B43 | C5: 203 | D5: 152 | E5: 254 | F5: 113365.56 | G5: 113325.26 | H5: 113405.87 | I5: =ABS(H5-G5) -> 80.617645 | J5: =G5-F5 -> -40.308823 | K5: =H5-F5 -> 40.308823
A6: PCI share, state 3 | B6: E45 | C6: 0.1 | D6: 0.05 | E6: 0.3 | F6: 113365.56 | G6: 113438.8 | H6: 113072.63 | I6: =ABS(H6-G6) -> 366.17423 | J6: =G6-F6 -> 73.234845 | K6: =H6-F6 -> -292.93938
A7: Angiogram cost | B7: B44 | C7: 1685 | D7: 1264 | E7: 2106 | F7: 113365.56 | G7: 112879.51 | H7: 113851.62 | I7: =ABS(H7-G7) -> 972.10276 | J7: =G7-F7 -> -486.05138 | K7: =H7-F7 -> 486.05138
A8: Decrement, state 2 | B8: dec_2 | C8: 0.05 | D8: 0.025 | E8: 0.075 | F8: 113365.56 | G8: 115793.88 | H8: 111037 | I8: =ABS(H8-G8) -> 4756.8776 | J8: =G8-F8 -> 2428.3171 | K8: =H8-F8 -> -2328.5605
A9: Decrement, state 3 | B9: dec_3 | C9: 0.15 | D9: 0.075 | E9: 0.225 | F9: 113365.56 | G9: 118127.61 | H9: 108972.58 | I9: =ABS(H9-G9) -> 9155.0354 | J9: =G9-F9 -> 4762.05 | K9: =H9-F9 -> -4392.9853
A10: Utility, no CAV | B10: u_1 | C10: 0.76 | D10: 0.71 | E10: 0.81 | F10: 113365.56 | G10: 120310.59 | H10: 107178.59 | I10: =ABS(H10-G10) -> 13131.999 | J10: =G10-F10 -> 6945.0272 | K10: =H10-F10 -> -6186.9718
A11: Discount rate | B11: disc | C11: 0.035 | D11: 0 | E11: 0.06 | F11: 113365.56 | G11: 88403.287 | H11: 134375.47 | I11: =ABS(H11-G11) -> 45972.182 | J11: =G11-F11 -> -24962.278 | K11: =H11-F11 -> 21009.904
A12: RR | B12: RR | C12: 0.68 | D12: 0.5 | E12: 0.9 | F12: 113365.56 | G12: 70776.055 | H12: 384691.89 | I12: =ABS(H12-G12) -> 313915.84 | J12: =G12-F12 -> -42589.509 | K12: =H12-F12 -> 271326.33

Sheet 9_PSA
A1: in progress
